Workbook

Sheet CERTIFICACIÓN REV 1
A1: 8000045901 - SERVICIO DE MANTENIMIENTO INTERGRADO Marzo -26
K4: MANTENIMINETO DE AIRE ACONDICIONADO | N4: 0.5
A5: PAGO BASICO MENSUAL | E5: 30832490 | K5: MANTENIMINETO ELECTRICO | N5: 0.4
K6: GRUPO GENERADOR | N6: 0.1
A7: PORCENTAJE CUMPLIMIENTO MENSUAL | E7: 1 | H7: CTA. MAYOR | I7: 41071005 | K7: TOTAL DE SERVICIO | N7: =+SUM(N4:N6) -> 1
A9: MATERIALES - HH A CERTIFICAR | H9: HES
L10: Disponibilidad | N10: 1
A11: TOTAL A CERTIFICAR | E11: =+E5*E7 -> 30832490 | L11: Plan correctivo | N11: 1
A13: IMPUTACIONES SERVICIO BASICO MENSUAL
D14: PLANTA | F14: CUENTA | G14: CeCO | H14: % | I14: Monto
D15: PLANTA CELULOSA | F15: 41071005 | G15: APCES1-348 | H15: 12 | I15: =+($E$11/100)*H15 -> 3699898.8 | J15: =+H15/100 -> 0.12
D16: FORESTAL | F16: 41071005 | G16: APFES1-714 | H16: 4.57 | I16: =+($E$11/100)*H16 -> 1409044.8 | J16: =+H16/100 -> 0.0457
D17: FORESTAL | F17: 41111002 | G17: APFES1-201 | H17: 13.17 | I17: =+($E$11/100)*H17 -> 4060638.9 | J17: =+H17/100 -> 0.1317
D18: FORESTAL | F18: 41071005 | G18: APFES1-713 | H18: 3.48 | I18: =+($E$11/100)*H18 -> 1072970.6 | J18: =+H18/100 -> 0.0348
D19: FORESTAL | F19: 41071005 | G19: APFES1-701 | H19: 5.31 | I19: =+($E$11/100)*H19 -> 1637205.2 | J19: =+H19/100 -> 0.0531
D20: FORESTAL | F20: 41071005 | G20: APFES1-711 | H20: 3.77 | I20: =+($E$11/100)*H20 -> 1162384.9 | J20: =+H20/100 -> 0.0377
D21: SSGG CELULOSA | F21: 41071005 | G21: APOBA1-871 | H21: 8.46 | I21: =+($E$11/100)*H21 -> 2608428.6 | J21: =+H21/100 -> 0.0846
D22: SSGG BOSSEETTI | F22: 41071005 | G22: APOBA1-872 | H22: 11.16 | I22: =+($E$11/100)*H22 -> 3440905.8 | J22: =+H22/100 -> 0.1116
D23: EXPEDICION BOSSETTI | F23: 41071005 | G23: APOBA1-867 | H23: 5 | I23: =+($E$11/100)*H23 -> 1541624.5 | J23: =+H23/100 -> 0.05
D24: HOTEL PTO. PIRAY | F24: 41071005 | G24: APOBA1-875 | H24: 10.56 | I24: =+($E$11/100)*H24 -> 3255910.9 | J24: =+H24/100 -> 0.1056
D25: SSGG YPORA | F25: 41071005 | G25: APOBA1-885 | H25: 9.96 | I25: =+($E$11/100)*H25 -> 3070916 | J25: =+H25/100 -> 0.0996
D26: HOSTERIA | F26: 41071005 | G26: APOBA1-886 | H26: 12.56 | I26: =+($E$11/100)*H26 -> 3872560.7 | J26: =+H26/100 -> 0.1256
A27: TOTAL GRAL | H27: 100 | I27: =+SUM(I15:I26) -> 30832490
A31: % CUMPLIMINETO AIRE | D31: =+(D74+H74+L74+P74)/4 -> 0.4726175 | N31: OBJETIVO | O31: MENSUAL | P31: TRIMESTRALES | Q31: SEMESTRAL | R31: ANUAL | S31: TOTAL/MES
A32: % DE INCIDENCIA DEL SERVICIO | D32: 0.5 | N32: Celulosa | O32: 18 | P32: 4 | Q32: 15 | R32: 43 | S32: =+SUM(O32:R32) -> 80
N33: Bossetti | O33: 5 | P33: 1 | Q33: 8 | R33: 10 | S33: =+SUM(O33:R33) -> 24
N34: Y-Pora | O34: 7 | P34: 5 | Q34: 30 | R34: 41 | S34: =+SUM(O34:R34) -> 83
N35: Piray | O35: 6 | P35: 1 | Q35: 9 | R35: 28 | S35: =+SUM(O35:R35) -> 44
N37: TOTAL/MES | O37: =SUM(O32:O36) -> 36 | P37: =+SUM(P32:P36)/3 -> 3.6666667 | Q37: =+SUM(Q32:Q36)/6 -> 10.333333 | R37: =+SUM(R32:R36)/12 -> 10.166667 | S37: =+SUM(S32:S36) -> 231
A39: INTERVENSIONES REFRIGERACION
A40: N° | B40: MES | C40: MENSUALES 36 equipos | E40: TRIMESTRALES ( 11 equipos) | I40: SEMESTRALES (62 equipos) | M40: ANUALES ( 122 equipos) | Q40: INTERVENCIONES
C41: INTER | D41: CUMPL | E41: INTER | F41: ACUM | G41: ACUM PLA | H41: CUMPL | I41: Intervensiones | J41: Acumulado | K41: Acum. Plan. | L41: Cumplimiento | M41: Intervensiones | N41: Acumulado | O41: Acum. Plan. | P41: Cumplimiento | Q41: Planificadas | R41: No Planif | S41: TOTAL
A42: 1 | B42: 44287 | C42: =COUNTIF('BASE AA'!#REF!,"=1") -> #REF! | D42: =+C42/$O$37 -> #REF! | E42: =COUNTIF('BASE AA'!#REF!,"=2") -> #REF! | F42: =+E42 -> #REF! | G42: =+P37 -> 3.6666667 | H42: =F42/G42 -> #REF! | I42: =COUNTIF('BASE AA'!#REF!,"=3") -> #REF! | J42: =+I42 -> #REF! | K42: =+Q37 -> 10.333333 | L42: =J42/K42 -> #REF! | M42: =COUNTIF('BASE AA'!#REF!,"=4") -> #REF! | N42: =+M42 -> #REF! | O42: =+R37 -> 10.166667 | P42: =+N42/O42 -> #REF! | Q42: =+I42+E42+C42+M42 -> #REF! | R42: 8 | S42: =+R42+Q42 -> #REF!
A43: =+A42+1 -> 2 | B43: 44317 | C43: =COUNTIF('BASE AA'!#REF!,"=1") -> #REF! | D43: =+C43/$O$37 -> #REF! | E43: =COUNTIF('BASE AA'!#REF!,"=2") -> #REF! | F43: =+F42+E43 -> #REF! | G43: =A43*$G$42 -> 7.3333333 | H43: =F43/G43 -> #REF! | I43: =COUNTIF('BASE AA'!#REF!,"=3") -> #REF! | J43: =+J42+I43 -> #REF! | K43: =A43*$K$42 -> 20.666667 | L43: =J43/K43 -> #REF! | M43: =COUNTIF('BASE AA'!#REF!,"=4") -> #REF! | N43: =+M43+N42 -> #REF! | O43: =+A43*$O$42 -> 20.333333 | P43: =+N43/O43 -> #REF! | Q43: =+I43+E43+C43+M43 -> #REF! | R43: 7 | S43: =+R43+Q43 -> #REF!
A44: =+A43+1 -> 3 | B44: 44348 | C44: =COUNTIF('BASE AA'!#REF!,"=1") -> #REF! | D44: =+C44/$O$37 -> #REF! | E44: =COUNTIF('BASE AA'!#REF!,"=2") -> #REF! | F44: =+F43+E44 -> #REF! | G44: =A44*$G$42 -> 11 | H44: =F44/G44 -> #REF! | I44: =COUNTIF('BASE AA'!#REF!,"=3") -> #REF! | J44: =+J43+I44 -> #REF! | K44: =A44*$K$42 -> 31 | L44: =J44/K44 -> #REF! | M44: =COUNTIF('BASE AA'!#REF!,"=4") -> #REF! | N44: =+M44+N43 -> #REF! | O44: =+A44*$O$42 -> 30.5 | P44: =+N44/O44 -> #REF! | Q44: =+I44+E44+C44+M44 -> #REF! | R44: 4 | S44: =+R44+Q44 -> #REF!
A45: =+A44+1 -> 4 | B45: 44378 | C45: =COUNTIF('BASE AA'!#REF!,"=1") -> #REF! | D45: =+C45/$O$37 -> #REF! | E45: =COUNTIF('BASE AA'!#REF!,"=2") -> #REF! | F45: =+E45 -> #REF! | G45: =+P37 -> 3.6666667 | H45: =F45/G45 -> #REF! | I45: =COUNTIF('BASE AA'!#REF!,"=3") -> #REF! | J45: =+J44+I45 -> #REF! | K45: =A45*$K$42 -> 41.333333 | L45: =J45/K45 -> #REF! | M45: =COUNTIF('BASE AA'!#REF!,"=4") -> #REF! | N45: =+M45+N44 -> #REF! | O45: =+A45*$O$42 -> 40.666667 | P45: =+N45/O45 -> #REF! | Q45: =+I45+E45+C45+M45 -> #REF! | R45: 8 | S45: =+R45+Q45 -> #REF!
A46: =+A45+1 -> 5 | B46: 44409 | C46: =COUNTIF('BASE AA'!#REF!,"=1") -> #REF! | D46: =+C46/$O$37 -> #REF! | E46: =COUNTIF('BASE AA'!#REF!,"=2") -> #REF! | F46: =+F45+E46 -> #REF! | G46: =+G45*A43 -> 7.3333333 | H46: =F46/G46 -> #REF! | I46: =COUNTIF('BASE AA'!#REF!,"=3") -> #REF! | J46: =+J45+I46 -> #REF! | K46: =A46*$K$42 -> 51.666667 | L46: =J46/K46 -> #REF! | M46: =COUNTIF('BASE AA'!#REF!,"=4") -> #REF! | N46: =+M46+N45 -> #REF! | O46: =+A46*$O$42 -> 50.833333 | P46: =+N46/O46 -> #REF! | Q46: =+I46+E46+C46+M46 -> #REF! | R46: 10 | S46: =+R46+Q46 -> #REF!
A47: =+A46+1 -> 6 | B47: 44440 | C47: =COUNTIF('BASE AA'!#REF!,"=1") -> #REF! | D47: =+C47/$O$37 -> #REF! | E47: 12 | F47: =+F46+E47 -> #REF! | G47: =+G45*A44 -> 11 | H47: =F47/G47 -> #REF! | I47: =COUNTIF('BASE AA'!#REF!,"=3") -> #REF! | J47: =+J46+I47 -> #REF! | K47: =A47*$K$42 -> 62 | L47: =J47/K47 -> #REF! | M47: =COUNTIF('BASE AA'!#REF!,"=4") -> #REF! | N47: =+M47+N46 -> #REF! | O47: =+A47*$O$42 -> 61 | P47: =+N47/O47 -> #REF! | Q47: =+I47+E47+C47+M47 -> #REF! | R47: 19 | S47: =+R47+Q47 -> #REF!
A48: =+A47+1 -> 7 | B48: 44470 | C48: =COUNTIF('BASE AA'!#REF!,"=1") -> #REF! | D48: =+C48/$O$37 -> #REF! | E48: 9 | F48: =+E48 -> 9 | G48: =+P37 -> 3.6666667 | H48: =F48/G48 -> 2.4545455 | I48: =COUNTIF('BASE AA'!#REF!,"=3") -> #REF! | J48: =+I48 -> #REF! | K48: 14 | L48: =J48/K48 -> #REF! | M48: =COUNTIF('BASE AA'!#REF!,"=4") -> #REF! | N48: =+M48+N47 -> #REF! | O48: =+A48*$O$42 -> 71.166667 | P48: =+N48/O48 -> #REF! | Q48: =+I48+E48+C48+M48 -> #REF! | R48: 21 | S48: =+R48+Q48 -> #REF!
A49: =+A48+1 -> 8 | B49: 44501 | C49: =COUNTIF('BASE AA'!#REF!,"=1") -> #REF! | D49: =+C49/$O$37 -> #REF! | E49: =COUNTIF('BASE AA'!#REF!,"=2") -> #REF! | F49: =+F48+E49 -> #REF! | G49: =+G48*A43 -> 7.3333333 | H49: =F49/G49 -> #REF! | I49: =COUNTIF('BASE AA'!#REF!,"=3") -> #REF! | J49: =+J48+I49 -> #REF! | K49: 28 | L49: =J49/K49 -> #REF! | M49: =COUNTIF('BASE AA'!#REF!,"=4") -> #REF! | N49: =+M49+N48 -> #REF! | O49: =+A49*$O$42 -> 81.333333 | P49: =+N49/O49 -> #REF! | Q49: =+I49+E49+C49+M49 -> #REF! | R49: 20 | S49: =+R49+Q49 -> #REF!
...

Sheet CORRECTIVOS
B3: Aviso | C3: CECO | D3: UT | E3: Tarea | F3: Actividad | G3: Fecha | H3: Planificado | I3: Cumplido | J3: No planificado
F4: Electrico | G4: 46056 | H4: 1 | I4: SÍ
F5: Electrico | G5: 46057 | H5: 1 | I5: SÍ
F6: Hidrogrua | G6: 46057 | H6: 1 | I6: SÍ
F7: Electrico | G7: 46058 | H7: 1 | I7: SÍ
F8: Electrico | G8: 46058 | H8: 1 | I8: SÍ
F9: Electrico | G9: 46059 | H9: 1 | I9: SÍ
F10: Grupo Gen | G10: 46061 | I10: SÍ | J10: 1
F11: Electrico | G11: 46062 | H11: 1 | I11: SÍ
F12: Electrico | G12: 46062 | H12: 1 | I12: SÍ
F13: Grupo Gen | G13: 46062 | I13: SÍ | J13: 1
F14: Electrico | G14: 46063 | H14: 1 | I14: SÍ
F15: Electrico | G15: 46064 | H15: 1 | I15: SÍ
F16: Electrico | G16: 46064 | H16: 1 | I16: SÍ
F17: Electrico | G17: 46064 | H17: 1 | I17: SÍ
F18: Aire | G18: 46064 | I18: SÍ | J18: 1
F19: Electrico | G19: 46065 | H19: 1 | I19: SÍ
F20: Electrico | G20: 46065 | I20: SÍ | J20: 1
F21: Aire | G21: 46065 | H21: 1 | I21: SÍ
F22: Electrico | G22: 46066 | I22: SÍ | J22: 1
F23: Aire | G23: 46071 | H23: 1 | I23: SÍ
F24: Aire | G24: 46073 | H24: 1 | I24: SÍ
F25: Grupo Gen | G25: 46074 | I25: SÍ | J25: 1
F26: Aire | G26: 46076 | H26: 1 | I26: SÍ
F27: Electrico | G27: 46078 | H27: 1 | I27: SÍ
F28: Electrico | G28: 46078 | H28: 1 | I28: SÍ
F29: Aire | G29: 46078 | H29: 1 | I29: SÍ
F30: Aire | G30: 46078 | I30: SÍ | J30: 1
F31: Aire | G31: 46079 | H31: 1 | I31: SÍ
F32: Electrico | G32: 46080 | H32: 1 | I32: SÍ
F33: Electrico | G33: 46080 | H33: 1 | I33: SÍ
H35: =COUNT(H4:H33) -> 23 | I35: =+COUNTIF(I4:I34,"Sí") -> 30 | J35: =SUM(J4:J33) -> 7
H36: Porc. Cumplimiento
H37: =(+H35+J35)/I35 -> 1

Sheet BASE AA
A1: LOCALIDAD | B1: SEDE | C1: AREA | D1: CECO | E1: SECTOR/USUARIO | F1: DESCRIPCIÓN | G1: COD. NUEVO | H1: FREC | I1: 45597 | J1: 45627 | K1: 45658 | L1: 45689 | M1: 45717 | N1: 45748 | O1: 45778 | P1: 45809 | Q1: 45839 | R1: 45870 | S1: 45901 | T1: 45931 | U1: 45962 | V1: 45992 | W1: 46023 | X1: 46054 | Y1: 46082
A2: ESPERANZA | B2: PLANTA CELULOSA | C2: ADMINISTRACIÓN | D2: APOBA1-871 | E2: ESPE-ESP-CEL-ADMIN1-OFRRHH01 | F2: OF. RRHH CELULOSA | G2: CEL-AD1-1 | H2: 3 | P2: 3
A3: ESPERANZA | B3: PLANTA CELULOSA | C3: ADMINISTRACIÓN | D3: APOBA1-871 | E3: ESPE-ESP-CEL-ADMIN1-OFMASSO3 | F3: OF. JEFE DE SEGURIDAD. GRACIELA BENITEZ | G3: CEL-AD1-11 | H3: 4
A4: ESPERANZA | B4: PLANTA CELULOSA | C4: ADMINISTRACIÓN | D4: APOBA1-871 | E4: ESPE-ESP-CEL-ADMIN1-OFCOSTO1 | F4: Of. Costos (Auxiliares) | G4: CEL-AD1-9 | H4: 4 | O4: 4
A5: ESPERANZA | B5: PLANTA CELULOSA | C5: ADMINISTRACIÓN | D5: APOBA1-871 | E5: ESPE-ESP-CEL-ADMIN1-OFMASSO5 | F5: MASSO SALA DE REUNIONES | G5: CEL-AD1-13 | H5: 4
A6: ESPERANZA | B6: PLANTA CELULOSA | C6: ADMINISTRACIÓN | D6: APOBA1-871 | E6: ESPE-ESP-CEL-ADMIN1-OFMASSO4 | F6: Of. Supervisor Seguridad y Salud E CABRERA | G6: CEL-AD1-12 | H6: 4
A7: ESPERANZA | B7: PLANTA CELULOSA | C7: ADMINISTRACIÓN | D7: APOBA1-871 | E7: ESPE-ESP-CEL-ADMIN1-OFMASSO4 | F7: Of. Medio Ambiente (Auxiliares) | G7: CEL-AD1-14 | H7: 4 | P7: 4
A8: ESPERANZA | B8: PLANTA CELULOSA | C8: ADMINISTRACIÓN | D8: APOBA1-871 | E8: ESPE-ESP-CEL-ADMIN1-OFMASSO3 | F8: DANIEL CABRERA | G8: CEL-AD1-8 | H8: 4 | T8: 4
A9: ESPERANZA | B9: PLANTA CELULOSA | C9: ADMINISTRACIÓN | D9: APOBA1-871 | E9: ESPE-ESP-CEL-ADMIN1-OFSESUBA | F9: Of. Jefe de Costos ESCALADA LIZANDRO | G9: CEL-AD1-23 | H9: 4 | I9: 4
A10: ESPERANZA | B10: PLANTA CELULOSA | C10: ADMINISTRACIÓN | D10: APOBA1-871 | E10: ESPE-ESP-CEL-ADMIN1 | F10: Of. Tesorería | G10: CEL-AD1-20 | H10: 4 | O10: 4
A11: ESPERANZA | B11: PLANTA CELULOSA | C11: ADMINISTRACIÓN | D11: APOBA1-871 | E11: ESPE-ESP-CEL-ADMIN1-OFGEREOP | F11: OF. GERENTE OPERACIONES. | G11: CEL-AD1-25 | H11: 3 | O11: 3
A12: ESPERANZA | B12: PLANTA CELULOSA | C12: ADMINISTRACIÓN | D12: APOBA1-871 | E12: ESPE-ESP-CEL-ADMIN1-OFSECGTE | F12: Of. Secretaria Gte. | G12: CEL-AD1-26 | H12: 3 | N12: 3 | T12: 3
A13: ESPERANZA | B13: PLANTA CELULOSA | C13: ADMINISTRACIÓN | D13: APOBA1-871 | E13: ESPE-ESP-CEL-ADMIN1-OFRRHH01 | F13: Of. RRHH (Auxiliares) 2 | G13: CEL-AD1-2 | H13: 3 | P13: 3
A14: ESPERANZA | B14: PLANTA CELULOSA | C14: ADMINISTRACIÓN | D14: APOBA1-871 | E14: ESPE-ESP-CEL-ADMIN1-OFSGTEAD | F14: OF.SUBG.ADMINISTRACION. | G14: CEL-AD1-22 | H14: 4 | O14: 4
A15: ESPERANZA | B15: PLANTA CELULOSA | C15: ADMINISTRACIÓN | D15: APOBA1-871 | E15: ESPE-ESP-CEL-ADMIN1-OFSGTEMT | F15: Of. SubGerente de Mantenimiento | G15: CEL-AD1-21 | H15: 4 | O15: 4
A16: ESPERANZA | B16: PLANTA CELULOSA | C16: ADMINISTRACIÓN | D16: APOBA1-871 | E16: ESPE-ESP-CEL-ADMIN1-OFSGTEPR | F16: Of. SubGerente de Producción | G16: CEL-AD1-24 | H16: 4 | J16: 4
A17: ESPERANZA | B17: PLANTA CELULOSA | C17: ADMINISTRACIÓN | D17: APOBA1-871 | E17: ESPE-ESP-CEL-ADMIN1-ENFERME3 | F17: CONSULTORIO 1 | G17: PC01AD115 | H17: 1 | I17: 1 | J17: 1 | K17: 1 | L17: 1 | M17: 1 | N17: 1 | O17: 1 | P17: 1 | Q17: 1 | R17: 1 | S17: 1 | T17: 1 | U17: 1 | V17: 1 | W17: 1
A18: ESPERANZA | B18: PLANTA CELULOSA | C18: ADMINISTRACIÓN | D18: APOBA1-871 | E18: ESPE-ESP-CEL-ADMIN1-ENFERME3 | F18: CONSULTORIO 2 | G18: PC01AD116 | H18: 1 | I18: 1 | J18: 1 | K18: 1 | L18: 1 | M18: 1 | N18: 1 | O18: 1 | P18: 1 | Q18: 1 | R18: 1 | S18: 1 | T18: 1 | U18: 1 | V18: 1 | W18: 1
A19: ESPERANZA | B19: PLANTA CELULOSA | C19: ADMINISTRACIÓN | D19: APOBA1-871 | E19: ESPE-ESP-CEL-ADMIN1-ENFERME3 | F19: RECEPCIÓN ENFERMERIA. | G19: PC01AD118 | H19: 1 | I19: 1 | J19: 1 | K19: 1 | L19: 1 | M19: 1 | N19: 1 | O19: 1 | P19: 1 | Q19: 1 | R19: 1 | S19: 1 | T19: 1 | U19: 1 | V19: 1 | W19: 1
A20: ESPERANZA | B20: PLANTA CELULOSA | C20: ADMINISTRACIÓN | D20: APOBA1-871 | E20: ESPE-ESP-CEL-ADMIN1-ENFERME4 | F20: CONSULTORIO ENFERMERIA | G20: PC01AD117 | H20: 1 | I20: 1 | J20: 1 | K20: 1 | L20: 1 | M20: 1 | N20: 1 | O20: 1 | P20: 1 | Q20: 1 | R20: 1 | S20: 1 | T20: 1 | U20: 1 | V20: 1 | W20: 1
A21: ESPERANZA | B21: PLANTA CELULOSA | C21: ADMINISTRACIÓN | D21: APOBA1-871 | E21: ESPE-ESP-CEL-ADMIN1-SALREU01 | F21: SALA DE REUNIONES RR.HH. | G21: CEL-AD1-3 | H21: 3 | O21: 3
A22: ESPERANZA | B22: PLANTA CELULOSA | C22: ADMINISTRACIÓN | D22: APOBA1-871 | E22: ESPE-ESP-CEL-ADMIN1-OFJEFERH | F22: Of. Jefe de Área RRHH | G22: CEL-AD1-4 | H22: 4 | T22: 4
A23: ESPERANZA | B23: PLANTA CELULOSA | C23: ADMINISTRACIÓN | D23: APOBA1-871 | E23: ESPE-ESP-CEL-ADMIN1-OFAUINT1 | F23: Of. Jefe Auditoría Interna | G23: CEL-AD1-5 | H23: 4 | Q23: 4
A24: ESPERANZA | B24: PLANTA CELULOSA | C24: ADMINISTRACIÓN | D24: APOBA1-871 | E24: ESPE-ESP-CEL-ADMIN1-OFAUINT2 | F24: Of. Auditoría Interna (Auxiliar) | G24: CEL-AD1-6 | H24: 4 | Q24: 4
A25: ESPERANZA | B25: PLANTA CELULOSA | C25: ADMINISTRACIÓN | D25: APOBA1-871 | E25: ESPE-ESP-CEL-ADMIN1-OFCONPRO | F25: Of. Control de Producción | G25: CEL-AD1-10 | H25: 4 | T25: 4
A26: ESPERANZA | B26: PLANTA CELULOSA | C26: ADMINISTRACIÓN | D26: APOBA1-871 | E26: ESPE-ESP-CEL-ADMIN1-OFCONFO2 | F26: Of. Control Forestal (Auxiliares) | G26: CEL-AD1-7 | H26: 4 | P26: 4
A27: ESPERANZA | B27: PLANTA CELULOSA | C27: ADMINISTRACIÓN | D27: APOBA1-871 | E27: ESPE-ESP-CEL-ADMIN1-OFMASSO2 | F27: Of. MASSO (Auxiliar SySO) | G27: CEL-AD1-19 | H27: 4 | P27: 4
A28: ESPERANZA | B28: PLANTA CELULOSA | C28: ADMINISTRACIÓN | D28: APOBA1-871 | E28: ESPE-ESP-CEL-ADMIN1 | F28: OFICINA DE VICITAS GERENCIA | G28: CEL-AD1-28 | H28: 4 | S28: 4
A29: ESPERANZA | B29: PLANTA CELULOSA | C29: ADMINISTRACIÓN | D29: APOBA1-871 | E29: ESPE-ESP-CEL-ADMIN1-EXAPUNTADORES | F29: OFICINAS SOEP | G29: CEL-AD1-27 | H29: 4
A30: ESPERANZA | B30: PLANTA CELULOSA | C30: ADMINISTRACIÓN 2 | D30: APOBA1-871 | E30: ESPE-ESP-CEL-ADMIN2-OFICINA1 | F30: Of. SSGG (Supervisor) | G30: CEL-AD2-1 | H30: 4 | O30: 4
A31: ESPERANZA | B31: PLANTA CELULOSA | C31: ADMINISTRACIÓN 2 | D31: APOBA1-871 | E31: ESPE-ESP-CEL-ADMIN2-OFCOYOB2 | F31: Of. Contratos y Obras (Auxiliares) | G31: CEL-AD2-10 | H31: 4 | R31: 4
A32: ESPERANZA | B32: PLANTA CELULOSA | C32: ADMINISTRACIÓN 2 | D32: APOBA1-871 | E32: ESPE-ESP-CEL-ADMIN2-OFJEFCYO | F32: Of. Jefe Contratos y Obras | G32: CEL-AD2-11 | H32: 4 | K32: 4 | R32: 4
A33: ESPERANZA | B33: PLANTA CELULOSA | C33: ADMINISTRACIÓN 2 | D33: APOBA1-871 | E33: ESPE-ESP-CEL-ADMIN2-OFCOYOB3 | F33: Of. Jefe Contrataciones Forestales | G33: CEL-AD2-12 | H33: 4 | R33: 4 | X33: 4
A34: ESPERANZA | B34: PLANTA CELULOSA | C34: ADMINISTRACIÓN 2 | D34: APOBA1-871 | E34: ESPE-ESP-CEL-ADMIN2-OFCOYOB1 | F34: Sala de reuniones Contratos y Obras | G34: CEL-AD2-13 | H34: 4 | R34: 4
A35: ESPERANZA | B35: PLANTA CELULOSA | C35: ADMINISTRACIÓN 2 | D35: APOBA1-871 | E35: ESPE-ESP-CEL-ADMIN2-SALCAP01 | F35: SALA DE CAPACITACIÓN CEL-AD2-14 | G35: CEL-AD2-14 | H35: 3 | O35: 3
A36: ESPERANZA | B36: PLANTA CELULOSA | C36: ADMINISTRACIÓN 2 | D36: APOBA1-871 | E36: ESPE-ESP-CEL-ADMIN2-SALCAP02 | F36: SALA DE CAPACITACIÓN CEL-AD2-15 | G36: CEL-AD2-15 | H36: 3 | O36: 3
A37: ESPERANZA | B37: PLANTA CELULOSA | C37: ADMINISTRACIÓN 2 | D37: APOBA1-871 | E37: ESPE-ESP-CEL-ADMIN2-SALCAP03 | F37: SALA DE CAPACITACIÓN CHICA CEL-AD2-16 | G37: CEL-AD2-16 | H37: 3 | O37: 3
A38: ESPERANZA | B38: PLANTA CELULOSA | C38: ADMINISTRACIÓN 2 | D38: APOBA1-871 | E38: ESPE-ESP-CEL-ADMIN2-OFCOSTOS | F38: Of. Jefe Cuentas a Pagar | G38: CEL-AD2-2 | H38: 4 | U38: 4
A39: ESPERANZA | B39: PLANTA CELULOSA | C39: ADMINISTRACIÓN 2 | D39: APOBA1-871 | E39: ESPE-ESP-CEL-ADMIN2-OFSGMOVI | F39: Of. SSGG (Auxiliares 1) | G39: CEL-AD2-3 | H39: 4 | T39: 4 | X39: 4
A40: ESPERANZA | B40: PLANTA CELULOSA | C40: ADMINISTRACIÓN 2 | D40: APOBA1-871 | E40: ESPE-ESP-CEL-ADMIN2-OFSGMOVI | F40: Of. SSGG (Movilidad) | G40: CEL-AD2-4 | H40: 4 | O40: 4
...

Sheet PROG AA
B1: Equipo | D1: abril | E1: mayo | F1: junio | G1: julio | H1: agosto | I1: septiembre | J1: octubre | K1: noviembre | L1: diciembre | M1: enero | N1: febrero | O1: marzo
A2: TRIMESTRALES | B2: CEL-FOR-1 | C2: 2 | D2: x | G2: x | J2: x | M2: x
B3: CEL-FOR-2 | C3: 2 | D3: x | G3: x | J3: x | M3: x
B4: CEL-FOR-3 | C4: 2 | D4: x | G4: x | J4: x | M4: x
B5: CEL-FOR-4 | C5: 2 | D5: x | G5: x | J5: x | M5: x
B6: CLO-VIG-1 | C6: 2 | F6: x | I6: x | L6: x | O6: x
B7: LOG-LOG-1 | C7: 2 | D7: x | G7: x | J7: x | M7: x
B8: MDF-AD1-10 | C8: 2 | E8: x | H8: x | K8: x | N8: x
B9: MDF-AD1-11 | C9: 2 | E9: x | H9: x | K9: x | N9: x
B10: MDF-AD1-16 | C10: 2 | E10: x | H10: x | K10: x | N10: x
B11: MDF-AD1-17 | C11: 2 | E11: x | H11: x | K11: x | N11: x
B12: MDF-AD1-18 | C12: 2 | F12: x | I12: x | L12: x | O12: x
B13: MDF-AD1-3 | C13: 2 | F13: x | I13: x | L13: x | O13: x
B14: MDF-AD1-6 | C14: 2 | F14: x | I14: x | L14: x | O14: x
B15: MDF-AD1-7 | C15: 2 | F15: x | I15: x | L15: x | O15: x
B16: MDF-AD1-8 | C16: 2 | F16: x | I16: x | L16: x | O16: x
B17: MDF-AD1-9 | C17: 2 | F17: x | I17: x | L17: x | O17: x
B18: MDF-AD2-2 | C18: 2 | D18: x | G18: x | J18: x | M18: x
B19: MDF-EXP-1 | C19: 2 | D19: x | G19: x | J19: x | M19: x
B20: MDF-EXP-2 | C20: 2 | D20: x | G20: x | J20: x | M20: x
B21: MDF-EXP-3 | C21: 2 | D21: x | G21: x | J21: x | M21: x
B22: MDF-LAB-1 | C22: 2 | E22: x | H22: x | K22: x | N22: x
B23: PYP-AD1-23 | C23: 2 | F23: x | I23: x | L23: x | O23: x
B24: PYP-AD1-29 | C24: 2 | E24: x | H24: x | K24: x | N24: x
B25: PYP-HOS-21 | C25: 2 | E25: x | H25: x | K25: x | N25: x
B26: PYP-POR-6 | C26: 2 | E26: x | H26: x | K26: x | N26: x
B27: PYP-SME-2 | C27: 2 | E27: x | H27: x | K27: x | N27: x
A30: SEMESTRALES | B30: Equipo | D30: abril | E30: mayo | F30: junio | G30: julio | H30: agosto | I30: septiembre | J30: octubre | K30: noviembre | L30: diciembre | M30: enero | N30: febrero | O30: marzo
B31: CEL-AD1-1 | C31: 3 | H31: X | N31: X
B32: CEL-AD1-25 | C32: 3 | E32: X | K32: X
B33: CEL-AD1-26 | C33: 3 | H33: X | N33: X
B34: CEL-AD1-2 | C34: 3 | E34: X | K34: X
B35: CEL-AD1-3 | C35: 3 | E35: X | K35: X
B36: CEL-AD2-14 | C36: 3 | E36: X | K36: X
B37: CEL-AD2-15 | C37: 3 | E37: X | K37: X
B38: CEL-AD2-16 | C38: 3 | E38: X | K38: X
B39: CEL-LOG-1 | C39: 3 | D39: X | J39: X
B40: CEL-LOG-2 | C40: 3 | D40: X | J40: X
B41: CEL-LOG-3 | C41: 3 | D41: X | J41: X
B42: CEL-LOG-4 | C42: 3 | D42: X | J42: X
...

Sheet  avisos AA 
A1: Frecuencia | B1: Fecha de aviso | C1: Fin deseado | D1: Aviso | E1: Orden | F1: Status usuario | G1: Denominación | H1: Descripción | I1: Centro coste | J1: Ubicac.técnica | K1: Centro PtoTbjo
A2: Mensuales
A38: Trimestrales
A42: Semestrales
A45: Anuales | D45: 11284060
D46: 11283966
D47: 11283969
A48: Correctivos | D48: 11365329
D49: 11361131
D50: 11343931
D51: 11347328
D52: 11349605
D53: 11363343
D54: 11365323
D55: 11353566

Sheet BASE ELEC
A1: LOCALIDAD | B1: SEDE | C1: AREA | E1: TAREA | F1: CECO | G1: FREC | H1: 45597 | I1: 45627 | J1: 45658 | K1: 45689 | L1: 45717 | M1: 45748 | N1: 45778 | O1: 45809 | P1: 45839 | Q1: 45870 | R1: 45901 | S1: 45931 | T1: 45962 | U1: 45992 | V1: 46023 | W1: 46054 | X1: 46082
A2: ESPERANZA | B2: Garita R 12 | C2: SECTORES COMUNES | D2: GARI-GAR-RUT-ADMIN1 | E2: * Iluminación de espacios Comunes | F2: APOBA1-885 | G2: 1 | H2: 1 | I2: 1 | J2: 1 | K2: 1 | L2: 1 | M2: 1 | N2: 1 | O2: 1 | P2: 1 | Q2: 1 | R2: 1 | S2: 1 | T2: 1 | U2: 1 | V2: 1 | W2: 46082
A3: ESPERANZA | B3: Garita R 12 | C3: OFICINAS | D3: GARI-GAR-RUT-ADMIN1-OFCAMTRA | E3: * Iluminación y tomas de oficinas, estac tech | F3: APFES1-711 | G3: 1 | H3: 1 | I3: 1 | J3: 1 | K3: 1 | L3: 1 | M3: 1 | N3: 1 | O3: 1 | P3: 1 | Q3: 1 | R3: 1 | S3: 1 | T3: 1 | U3: 1 | V3: 1 | W3: 46113
A4: ESPERANZA | B4: Garita R 12 | C4: COMEDOR | D4: GARI-GAR-RUT-ADMIN1-COMEDOR1 | E4: *Iluminación y tomas de Comedor | F4: APFES1-711 | G4: 1 | H4: 1 | I4: 1 | J4: 1 | K4: 1 | L4: 1 | M4: 1 | N4: 1 | O4: 1 | P4: 1 | Q4: 1 | R4: 1 | S4: 1 | T4: 1 | U4: 1 | V4: 1 | W4: 46143
A5: ESPERANZA | B5: Garita R 12 | C5: SALA DE CAPACITACION | D5: GARI-GAR-RUT-ADMIN1-SALCAP01 | E5: *Iluminación y tomas de sala de capacitación | F5: APFES1-711 | G5: 1 | H5: 1 | I5: 1 | J5: 1 | K5: 1 | L5: 1 | M5: 1 | N5: 1 | O5: 1 | P5: 1 | Q5: 1 | R5: 1 | S5: 1 | T5: 1 | U5: 1 | V5: 1 | W5: 46174
A6: ESPERANZA | B6: Garita R 12 | C6: SECTORES COMUNES | D6: GARI-GAR-RUT-ADMIN1 | E6: TABLEROS PRINCIPALES Y SECCIONALES | F6: APOBA1-885 | G6: 4 | L6: 4 | W6: 46204
A7: ESPERANZA | B7: Garita R 12 | C7: SECTORES COMUNES | D7: GARI-GAR-RUT-ADMIN1-BAADMIN1 | E7: * Iluminación y tomas de baños | F7: APOBA1-885 | G7: 1 | H7: 1 | I7: 1 | J7: 1 | K7: 1 | L7: 1 | M7: 1 | N7: 1 | O7: 1 | P7: 1 | Q7: 1 | R7: 1 | S7: 1 | T7: 1 | U7: 1 | V7: 1 | W7: 46235
A8: ESPERANZA | B8: Garita R 12 | C8: OFICINAS | D8: GARI-GAR-RUT-ADMIN1-VIVGUAPA | E8: * Iluminación y tomas casa de guarda parque | F8: APFES1-711 | G8: 1 | H8: 1 | I8: 1 | J8: 1 | K8: 1 | L8: 1 | M8: 1 | N8: 1 | O8: 1 | P8: 1 | Q8: 1 | R8: 1 | S8: 1 | T8: 1 | U8: 1 | V8: 1 | W8: 46266
A9: ESPERANZA | B9: C L Bossetti | C9: CHALET | D9: BOSS-BOS-ADM-CHALET | E9: Tomas e iluminacion Interior del chalet | F9: APOBA1-872 | G9: 1 | H9: 1 | I9: 1 | J9: 1 | K9: 1 | L9: 1 | M9: 1 | N9: 1 | O9: 1 | P9: 1 | Q9: 1 | R9: 1 | S9: 1 | T9: 1 | U9: 1 | V9: 1 | W9: 46296
A10: ESPERANZA | B10: C L Bossetti | C10: CHALET | D10: BOSS-BOS-ADM-CHALET-PILETA01 | E10: Tomas e ilumina exterior del Chalet | F10: APOBA1-872 | G10: 1 | H10: 1 | I10: 1 | J10: 1 | K10: 1 | L10: 1 | M10: 1 | N10: 1 | O10: 1 | P10: 1 | Q10: 1 | R10: 1 | S10: 1 | T10: 1 | U10: 1 | V10: 1 | W10: 46327
A11: ESPERANZA | B11: C L Bossetti | C11: CHALET | D11: BOSS-BOS-ADM-CHALET-TABLEROS | E11: Rotulado de tablero | F11: APOBA1-872 | G11: 4 | W11: 46357
A12: ESPERANZA | B12: C L Bossetti | C12: CHALET | D12: BOSS-BOS-ADM-CASACU | E12: Iluminación ext perim casa cuidador | F12: APOBA1-872 | G12: 1 | H12: 1 | I12: 1 | J12: 1 | K12: 1 | L12: 1 | M12: 1 | N12: 1 | O12: 1 | P12: 1 | Q12: 1 | R12: 1 | S12: 1 | T12: 1 | U12: 1 | V12: 1 | W12: 46388
A13: ESPERANZA | B13: C L Bossetti | C13: SECTORES COMUNES | D13: BOSS-BOS-ADM-ADMIN1 | E13: Iluminación ext sector ex administración | F13: APOBA1-872 | G13: 1 | H13: 1 | I13: 1 | J13: 1 | K13: 1 | L13: 1 | M13: 1 | N13: 1 | O13: 1 | P13: 1 | Q13: 1 | R13: 1 | S13: 1 | T13: 1 | U13: 1 | V13: 1 | W13: 46419
A14: ESPERANZA | B14: Club Residencia | C14: SECTORES COMUNES | D14: ESPE-ESP-CLU-CLUBRE | E14: Ilum de calles internas CLUB | F14: APOBA1-886 | G14: 2 | J14: 2 | M14: 2 | P14: 2 | S14: 2 | V14: 2 | W14: 46447
A15: ESPERANZA | B15: PREDIO YPORA | C15: SECTORES COMUNES | D15: YPOR-YPO | E15: Iluminacion de calles internas | F15: APOBA1-886 | G15: 1 | H15: 1 | I15: 1 | J15: 1 | K15: 1 | L15: 1 | M15: 1 | N15: 1 | O15: 1 | P15: 1 | Q15: 1 | R15: 1 | S15: 1 | T15: 1 | U15: 1 | V15: 1 | W15: 46478
A16: ESPERANZA | B16: PREDIO YPORA | C16: OFICINAS | D16: YPOR-YPO-GOF-ADMIN1 | E16: tomas e ilum de oficinas de GOF | F16: APFES1-701 | G16: 1 | H16: 1 | I16: 1 | J16: 1 | K16: 1 | L16: 1 | M16: 1 | N16: 1 | O16: 1 | P16: 1 | Q16: 1 | R16: 1 | S16: 1 | T16: 1 | U16: 1 | V16: 1 | W16: 46508
A17: ESPERANZA | B17: PREDIO YPORA | C17: OFICINAS | D17: YPOR-YPO-GOF-VIGILA | E17: Tomas e iluminación de vigilancia | F17: APOBA1-895 | G17: 1 | H17: 1 | I17: 1 | J17: 1 | K17: 1 | L17: 1 | M17: 1 | N17: 1 | O17: 1 | P17: 1 | Q17: 1 | R17: 1 | S17: 1 | T17: 1 | U17: 1 | V17: 1 | W17: 46539
A18: ESPERANZA | B18: PREDIO YPORA | C18: OFICINAS | D18: YPOR-YPO-GOF-LABORA | E18: Tomas e ilum de Laboratorios | F18: APFES1-714 | G18: 1 | H18: 1 | I18: 1 | J18: 1 | K18: 1 | L18: 1 | M18: 1 | N18: 1 | O18: 1 | P18: 1 | Q18: 1 | R18: 1 | S18: 1 | T18: 1 | U18: 1 | V18: 1 | W18: 46569
A19: ESPERANZA | B19: PREDIO YPORA | C19: HOTEL | D19: YPOR-YPO-HOT-PLANTA-HABIT | E19: Hostería Tomas e ilum | F19: APOBA1-886 | G19: 1 | H19: 1 | I19: 1 | J19: 1 | K19: 1 | L19: 1 | M19: 1 | N19: 1 | O19: 1 | P19: 1 | Q19: 1 | R19: 1 | S19: 1 | T19: 1 | U19: 1 | V19: 1 | W19: 46600
A20: ESPERANZA | B20: PREDIO YPORA | C20: HOTEL | D20: YPOR-YPO-HOT-PLANTA-PASILLO | E20: Hostería Tomas e ilum de pasillos | F20: APOBA1-886 | G20: 1 | H20: 1 | I20: 1 | J20: 1 | K20: 1 | L20: 1 | M20: 1 | N20: 1 | O20: 1 | P20: 1 | Q20: 1 | R20: 1 | S20: 1 | T20: 1 | U20: 1 | V20: 1 | W20: 46631
A21: ESPERANZA | B21: PREDIO YPORA | C21: HOTEL | D21: YPOR-YPO-HOT-HOTEL1-COCINA | E21: Hostería Tomas e ilum cocina | F21: APOBA1-886 | G21: 1 | H21: 1 | I21: 1 | J21: 1 | K21: 1 | L21: 1 | M21: 1 | N21: 1 | O21: 1 | P21: 1 | Q21: 1 | R21: 1 | S21: 1 | T21: 1 | U21: 1 | V21: 1 | W21: 46661
A22: ESPERANZA | B22: PREDIO YPORA | C22: HOTEL | D22: YPOR-YPO-HOT-HOTEL1-SALCOMED | E22: Hostería Tomas e ilum | F22: APOBA1-886 | G22: 1 | H22: 1 | I22: 1 | J22: 1 | K22: 1 | L22: 1 | M22: 1 | N22: 1 | O22: 1 | P22: 1 | Q22: 1 | R22: 1 | S22: 1 | T22: 1 | U22: 1 | V22: 1 | W22: 46692
A23: ESPERANZA | B23: PREDIO YPORA | C23: HOTEL | D23: YPOR-YPO-HOT-HOTEL1-LAVADERO | E23: Hostería Tomas e ilum de sec servicios | F23: APOBA1-886 | G23: 1 | H23: 1 | I23: 1 | J23: 1 | K23: 1 | L23: 1 | M23: 1 | N23: 1 | O23: 1 | P23: 1 | Q23: 1 | R23: 1 | S23: 1 | T23: 1 | U23: 1 | V23: 1 | W23: 46722
A24: ESPERANZA | B24: PREDIO YPORA | C24: HOTEL | D24: YPOR-YPO-HOT-HOTEL1-GIMNASIO | E24: Hostería Tomas e ilum de sector GIM | F24: APOBA1-886 | G24: 1 | H24: 1 | I24: 1 | J24: 1 | K24: 1 | L24: 1 | M24: 1 | N24: 1 | O24: 1 | P24: 1 | Q24: 1 | R24: 1 | S24: 1 | T24: 1 | U24: 1 | V24: 1 | W24: 46753
A25: ESPERANZA | B25: PREDIO YPORA | C25: HOTEL | D25: YPOR-YPO-HOT-HOTEL1-SALA REUN | E25: Hostería Tomas e ilum sec s reuniones | F25: APOBA1-886 | G25: 1 | H25: 1 | I25: 1 | J25: 1 | K25: 1 | L25: 1 | M25: 1 | N25: 1 | O25: 1 | P25: 1 | Q25: 1 | R25: 1 | S25: 1 | T25: 1 | U25: 1 | V25: 1 | W25: 46784
A26: ESPERANZA | B26: PREDIO YPORA | C26: HOTEL | D26: YPOR-YPO-HOT-EXTERN | E26: Hostería sector externo ( iluminación) | F26: APOBA1-886 | G26: 1 | H26: 1 | I26: 1 | J26: 1 | K26: 1 | L26: 1 | M26: 1 | N26: 1 | O26: 1 | P26: 1 | Q26: 1 | R26: 1 | S26: 1 | T26: 1 | U26: 1 | V26: 1 | W26: 46813
A27: ESPERANZA | B27: PREDIO YPORA | C27: HOTEL | D27: YPOR-YPO-HOT-TABLEROS | E27: Verificar tableros y rotular | F27: APOBA1-886 | G27: 4 | L27: 4 | W27: 46844
A28: ESPERANZA | B28: ESPERANZA B | C28: MZ 128 CASA 1 | D28: ESPE-ESP-ESB-MAN128-CASA0001 | E28: VERIFICAR ELEMENTOS DE PROTECCION | F28: APOBA1-886 | G28: 4 | T28: 4 | W28: 46874
A29: ESPERANZA | B29: ESPERANZA B | C29: MZ 128 CASA 2 | D29: ESPE-ESP-ESB-MAN128-CASA0002 | E29: VERIFICAR ELEMENTOS DE PROTECCION | F29: APOBA1-886 | G29: 4 | W29: 46905
A30: ESPERANZA | B30: ESPERANZA B | C30: MZ 128 CASA 3 | D30: ESPE-ESP-ESB-MAN128-CASA0003 | E30: VERIFICAR ELEMENTOS DE PROTECCION | F30: APOBA1-886 | G30: 4 | W30: 46935
A31: ESPERANZA | B31: ESPERANZA B | C31: MZ 129 CASA 1 | D31: ESPE-ESP-ESB-MAN129-CASA0001 | E31: VERIFICAR ELEMENTOS DE PROTECCION | F31: APOBA1-886 | G31: 4 | W31: 46966
A32: ESPERANZA | B32: ESPERANZA B | C32: MZ 129 CASA 2 | D32: ESPE-ESP-ESB-MAN129-CASA0002 | E32: VERIFICAR ELEMENTOS DE PROTECCION | F32: APOBA1-886 | G32: 4 | J32: 4 | W32: 46997
A33: ESPERANZA | B33: ESPERANZA B | C33: MZ 129 CASA 3 | D33: ESPE-ESP-ESB-MAN129-CASA0003 | E33: VERIFICAR ELEMENTOS DE PROTECCION | F33: APOBA1-886 | G33: 4 | P33: 4 | W33: 47027
A34: ESPERANZA | B34: ESPERANZA B | C34: MZ 129 CASA 4 | D34: ESPE-ESP-ESB-MAN129-CASA0004 | E34: VERIFICAR ELEMENTOS DE PROTECCION | F34: APOBA1-886 | G34: 4 | W34: 47058
A35: ESPERANZA | B35: ESPERANZA B | C35: MZ 130 CASA 1 | D35: ESPE-ESP-ESB-MAN130-CASA0001 | E35: VERIFICAR ELEMENTOS DE PROTECCION | F35: APOBA1-886 | G35: 4 | I35: 4 | Q35: 4 | W35: 47088
A36: ESPERANZA | B36: ESPERANZA B | C36: MZ 130 CASA 2 | D36: ESPE-ESP-ESB-MAN130-CASA0002 | E36: VERIFICAR ELEMENTOS DE PROTECCION | F36: APOBA1-886 | G36: 4 | Q36: 4 | W36: 47119
A37: ESPERANZA | B37: ESPERANZA B | C37: MZ 130 CASA 3 | D37: ESPE-ESP-ESB-MAN130-CASA0003 | E37: VERIFICAR ELEMENTOS DE PROTECCION | F37: APOBA1-886 | G37: 4 | K37: 4 | W37: 47150
A38: ESPERANZA | B38: ESPERANZA B | C38: MZ 130 CASA 4 | D38: ESPE-ESP-ESB-MAN130-CASA0004 | E38: VERIFICAR ELEMENTOS DE PROTECCION | F38: APOBA1-886 | G38: 4 | I38: 4 | T38: 4
A39: ESPERANZA | B39: ESPERANZA B | C39: MZ 130 CASA 5 | D39: ESPE-ESP-ESB-MAN130-CASA0005 | E39: VERIFICAR ELEMENTOS DE PROTECCION | F39: APOBA1-886 | G39: 4 | U39: 4
A40: ESPERANZA | B40: ESPERANZA B | C40: MZ 130 CASA 6 | D40: ESPE-ESP-ESB-MAN130-CASA0006 | E40: VERIFICAR ELEMENTOS DE PROTECCION | F40: APOBA1-886 | G40: 4
...

Sheet Avisos Elec
A1: Frecuencia | B1: Fecha de aviso | C1: Fin deseado | D1: Aviso | E1: Orden | F1: Status usuario | G1: Denominación | H1: Descripción | I1: Centro coste | J1: Ubicac.técnica | K1: Centro PtoTbjo
A2: MENSUALES
A48: Trimestrales
A50: Semestrales
A52: Anuales
A60: Correctivos | D60: 11359020
D61: 11356980
D62: 11358446
D63: 11358374
D64: 11359585
D65: 11345492
D66: 11358400
D67: 11358450
D68: 11342706
D69: 11342704
D70: 11358981
D71: 11361131
D72: 11338596
... D77: 11362381

Sheet BASE GE
B4: Sede | C4: UT | D4: Detalle | E4: Potencia | F4: Responsable | G4: CODIGO | H4: 45597 | I4: 45627 | J4: 45658 | K4: 45689 | L4: 45717 | M4: 45748 | N4: 45778 | O4: 45809 | P4: 45839 | Q4: 45658 | R4: 45689 | S4: 45717 | T4: 45748 | U4: 45778 | V4: 45809 | W4: 45839 | X4: 45870 | Y4: 45901 | Z4: 45931 | AA4: 45962 | AB4: 45992 | AC4: Fecha realizacion
A5: básico | B5: Bossetti | C5: BOSS-BOS-ADM-VIVERO | D5: Grupo Electrógeno Diésel | E5: 80 KVA | F5: Vivero | G5: GGE-80KVA-VIB | L5: Service | U5: Check | AA5: ** Service | AD5: 45982
A6: básico | B6: Y-Pora | C6: YPOR-YPO-GOF-VIVERO | D6: Grupo Electrógeno Diésel | E6: 132 KVA | F6: Vivero | G6: GGE-132KVA-VIB | H6: Check | T6: Service | AA6: Service | AD6: 45971
A7: básico | B7: Bossetti | C7: BOSS-BOS-ADM-CHALET | D7: Grupo Electrógeno Nafta | E7: 10 kVA | F7: SS.GG. | G7: GGE-12KVA-CHB | M7: Service
A8: básico | B8: Bossetti | C8: BOSS-BOS-ADM-ADMIN1 | D8: Grupo Electrógeno Diésel | E8: 31 kVA | F8: CLB | G8: GGE-31KVA-CLB | I8: Service | X8: Check
A9: básico | B9: Bossetti | C9: BOSS-BOS-ADM-ADMIN1 | D9: Grupo Electrógeno Nafta | E9: 7,5 KVA | F9: CLB | G9: GGE-7,5KVA-CLB | I9: Check | N9: Service | V9: Service | X9: Check
A10: básico | B10: Y-Pora | C10: YPOR-YPO-GOF- | D10: Grupo Electrógeno Diésel | E10: 164 KVA | F10: GOF | G10: GGE-164KVA-VYP | U10: Check | AA10: Check | AD10: 45971
A11: básico | B11: Y-Pora | C11: YPOR-YPO-HOT | D11: Grupo Electrógeno Diésel | E11: 100 KVA | F11: SS.GG. | G11: GGE-100KVA-HYP | L11: Service | T11: Service | AA11: Ckeck | AB11: 46008 | AD11: 45971 | AE11: 17/12/25 se cambio tablero con transferencia nueva
A12: básico | B12: Celulosa | C12: ESPE-ESP-CEL-BALANZ | D12: Grupo Electrógeno Nafta | E12: 10 KVA | F12: SS.GG. | G12: GGE-10KVA-BAC | R12: Check | U12: Service | AA12: Check | AD12: 45975
A13: básico | B13: Piray | C13: PIRA-PIR-MDF-BALANZ | D13: Grupo Electrógeno Nafta | E13: 7,5 KVA | F13: SS.GG. | G13: GGE-7,5KVA-BAP | O13: Service | R13: Ckeck | Z13: Service | AD13: 45931
A14: básico | B14: PALMITOS | C14: YPOR-YPO-GOF | D14: Grupo Electrógeno Diésel | E14: 31,3 KVA | F14: FORESTAL | G14: GGE-31,3KVA-PAL
A15: básico | B15: PALMITOS | C15: YPOR-YPO-GOF | D15: Grupo Electrógeno Nafta | E15: 7,5 KVA | F15: FORESTAL | G15: GGE-7,5KVA-PAL | H15: Service | M15: Service
A16: básico | B16: ELDORADO | C16: PIRA-PIR-ELD-CASGTE-KM8GTECE | D16: Grupo Electrógeno Nafta | E16: 11 KVA | F16: SS.GG. | G16: GGE-11KVA-GCE | H16: Service | V16: Check
A17: Adicional | B17: Celulosa | C17: ESPE-ESP-CEL-ADMIN2-OFSGTECO | D17: Grupo Electrógeno Nafta | E17: 11 KVA | F17: SS.GG. | G17: GGE-11KVA-DSG | N17: Check
A18: Adicional | B18: Bossetti | C18: BOSS-BOS-ADM-VIVERO | D18: Grupo Electrógeno Diésel | E18: 100 KVA | F18: Vivero | G18: GGE-100KVA-VIB | U18: Check | AA18: Service | AD18: 45982
A20: Basico | B20: Bosetti | C20: BOSS-BOS-ADM-CHALET | D20: Grupo Electrógeno Diésel | E20: 40 KVA | F20: Chalet | G20: PM02CLB40KVA | W20: Service
A22: ** correspondia un service, pero a pedido de Diego Olocco no se cambia el aceite

Sheet Avisos Generadores 
A1: Frecuencia | B1: Fecha de aviso | C1: Fin deseado | D1: Aviso | E1: Orden | F1: Status usuario | G1: Denominación | H1: Descripción | I1: Potencia | J1: Ubicac.técnica | K1: Centro PtoTbjo | L1: Fecha realizado

Sheet recursos
B2: Proveedor : SEAM Servicios Eléctricos S.R.L
B3: CM 3100000914
B4: Servicio Básico : Febrero 2026
N6: Planta | O6: (Todas)
A7: Fecha | B7: Día | C7: Mes | D7: Días Hábiles | E7: Clemente A. | F7: Tesari H | G7: Caceres Oscar | H7: Arevalo Oscar | I7: Gerardo | J7: Davalos Cesar
A8: 1 | B8: Domingo | C8: Febrero | N8: Etiquetas de fila | O8: Suma de TotalHs
A9: 2 | B9: Lunes | C9: Febrero | D9: 1 | E9: 1 | F9: 1 | G9: 1 | H9: 1 | I9: 1 | J9: 1 | N9: AQUINO CLEMENTE | O9: 4.5777778
A10: 3 | B10: Martes | C10: Febrero | D10: 1 | E10: 1 | F10: 1 | G10: 1 | H10: 1 | I10: 1 | J10: 1 | N10: AREVALOS OSCAR | O10: 3.2527778
A11: 4 | B11: Miércoles | C11: Febrero | D11: 1 | E11: 1 | F11: 1 | G11: 1 | H11: 1 | I11: 1 | J11: 1 | N11: CACERES OSCAR | O11: 3.2659722
A12: 5 | B12: Jueves | C12: Febrero | D12: 1 | E12: 1 | F12: 1 | G12: 1 | H12: 1 | I12: 1 | J12: 1 | N12: DAVALOS CESAR | O12: 2.9368056
A13: 6 | B13: Viernes | C13: Febrero | D13: 1 | E13: 1 | F13: 1 | G13: 1 | H13: 1 | I13: 1 | N13: DUARTE ANTONIO | O13: 4.5284722
A14: 7 | B14: Sábado | C14: Febrero | F14: 1 | N14: PEREYRA BRUNO | O14: 5.2527778
A15: 8 | B15: Domingo | C15: Febrero | N15: TESARI HECTOR | O15: 3.0520833
A16: 9 | B16: Lunes | C16: Febrero | D16: 1 | E16: 1 | F16: 1 | G16: 1 | H16: 1 | I16: 1 | J16: 1 | N16: WORONOWICZ GERARDO | O16: 7.0055556
A17: 10 | B17: Martes | C17: Febrero | D17: 1 | E17: 1 | F17: 1 | G17: 1 | H17: 1 | I17: 1 | J17: 1 | N17: Total general | O17: 33.872222
A18: 11 | B18: Miércoles | C18: Febrero | D18: 1 | E18: 1 | F18: 1 | G18: 1 | H18: 1 | I18: 1 | J18: 1
A19: 12 | B19: Jueves | C19: Febrero | D19: 1 | E19: 1 | F19: 1 | G19: 1 | H19: 1 | I19: 1 | J19: 1
A20: 13 | B20: Viernes | C20: Febrero | D20: 1 | E20: 1 | F20: 1 | G20: 1 | H20: 1 | I20: 1 | J20: 1
A21: 14 | B21: Sábado | C21: Febrero | F21: 1 | G21: 1 | J21: 1
A22: 15 | B22: Domingo | C22: Febrero
A23: 16 | B23: Lunes | C23: Febrero
A24: 17 | B24: Martes | C24: Febrero | F24: 1 | G24: 1 | J24: 1
A25: 18 | B25: Miércoles | C25: Febrero | D25: 1 | E25: 1 | F25: 1 | G25: 1 | H25: 1 | I25: 1 | J25: 1
A26: 19 | B26: Jueves | C26: Febrero | D26: 1 | E26: 1 | F26: 1 | G26: 1 | H26: 1 | I26: 1 | J26: 1
A27: 20 | B27: Viernes | C27: Febrero | D27: 1 | E27: 1 | F27: 1 | G27: 1 | H27: 1 | I27: 1 | J27: 1
A28: 21 | B28: Sábado | C28: Febrero | E28: 1 | G28: 1 | H28: 1 | J28: 1
A29: 22 | B29: Domingo | C29: Febrero
A30: 23 | B30: Lunes | C30: Febrero | D30: 1 | E30: 1 | F30: 1 | G30: 1 | H30: 1 | I30: 1 | J30: 1
A31: 24 | B31: Martes | C31: Febrero | D31: 1 | E31: 1 | F31: 1 | G31: 1 | H31: 1 | I31: 1 | J31: 1
A32: 25 | B32: Miércoles | C32: Febrero | D32: 1 | E32: 1 | F32: 1 | G32: 1 | H32: 1 | I32: 1 | J32: 1
A33: 26 | B33: Jueves | C33: Febrero | D33: 1 | E33: 1 | F33: 1 | G33: 1 | H33: 1 | I33: 1 | J33: 1
A34: 27 | B34: Viernes | C34: Febrero | D34: 1 | E34: 1 | F34: 1 | G34: 1 | H34: 1 | I34: 1 | J34: 1
A35: 28 | B35: Sábado | C35: Febrero
D37: =SUM(D8:D35) -> 18 | E37: =SUM(E8:E35) -> 19 | F37: =SUM(F8:F35) -> 21 | G37: =SUM(G8:G35) -> 21 | H37: =SUM(H8:H35) -> 19 | I37: =SUM(I8:I35) -> 18 | J37: =SUM(J8:J35) -> 20 | K37: =SUM(K8:K35) -> 0
C39: objetivo | D39: Proporcional por Recurso | K39: %
C40: =+D37 -> 18 | E40: =+E37*0.2 -> 3.8 | F40: =+F37*0.2 -> 4.2 | G40: =+G37*0.2 -> 4.2 | H40: =+H37*0.2 -> 3.8 | I40: =+I37*0.2 -> 3.6 | K40: =+SUM(E40:I40)/C40 -> 1.0888889
B44: Nota; a partir del 10/11/25 ingresan dos roles mas el sr Caceres Oscar (ayudante) y el sr Duarte Antonio (electricista)
D46: 1 | E46: Vacaciones, cubre Tesari Héctor
D47: 1 | E47: Vacaciones, cubre Duarte Antonio

Sheet Digicard
A1: 0000019137-SEAM SERVICIOS ELECTRONICOS S.R.L.
A2: OC 3100000914
A3: Legajo | B3: Empleado | C3: Entrada | D3: Salida | E3: TotalHs | F3: Planta
A4: 1-44279757 | B4: AREVALOS OSCAR | C4: 46029.37 | D4: 46029.379 | E4: 00:13 | F4: Ypora
A5: 1-44279757 | B5: AREVALOS OSCAR | C5: 46035.54 | D5: 46035.68 | E5: 03:22 | F5: Ypora
A6: 1-31472794 | B6: CACERES OSCAR | C6: 46060.785 | D6: 46060.808 | E6: 00:34 | F6: Aserradero Bossetti
A7: 1-31472794 | B7: CACERES OSCAR | C7: 46061.425 | D7: 46061.435 | E7: 00:15 | F7: Aserradero Bossetti
A8: 1-31472794 | B8: CACERES OSCAR | C8: 46066.307 | D8: 46066.633 | E8: 07:50 | F8: Aserradero Bossetti
A9: 1-31472794 | B9: CACERES OSCAR | C9: 46073.506 | D9: 46073.535 | E9: 00:42 | F9: Aserradero Bossetti
A10: 1-22233614 | B10: DAVALOS CESAR | C10: 46057.446 | D10: 46057.46 | E10: 00:20 | F10: Aserradero Bossetti
A11: 1-22233614 | B11: DAVALOS CESAR | C11: 46062.405 | D11: 46062.54 | E11: 03:14 | F11: Aserradero Bossetti
A12: 1-22233614 | B12: DAVALOS CESAR | C12: 46063.377 | D12: 46063.413 | E12: 00:52 | F12: Aserradero Bossetti
A13: 1-22233614 | B13: DAVALOS CESAR | C13: 46066.312 | D13: 46066.634 | E13: 07:43 | F13: Aserradero Bossetti
A14: 1-22233614 | B14: DAVALOS CESAR | C14: 46072.512 | D14: 46072.544 | E14: 00:45 | F14: Aserradero Bossetti
A15: 1-22233614 | B15: DAVALOS CESAR | C15: 46076.371 | D15: 46076.44 | E15: 01:39 | F15: Aserradero Bossetti
... A35: 1-44279757 | B35: AREVALOS OSCAR | C35: 46049.647 | D35: 46049.685 | E35: 00:56 | F35: Ypora
A36: 1-31472794 | B36: CACERES OSCAR | D36: 46055.427 | E36: 00:00 | F36: Piray
A37: 1-31472794 | B37: CACERES OSCAR | C37: 46055.479 | D37: 46055.491 | E37: 00:17 | F37: Piray
A38: 1-31472794 | B38: CACERES OSCAR | D38: 46055.748 | E38: 00:00 | F38: Piray
A39: 1-31472794 | B39: CACERES OSCAR | D39: 46064.406 | E39: 00:00 | F39: Piray
A40: 1-31472794 | B40: CACERES OSCAR | C40: 46064.665 | D40: 46064.672 | E40: 00:11 | F40: Piray
A41: 1-31472794 | B41: CACERES OSCAR | C41: 46064.719 | D41: 46064.726 | E41: 00:10 | F41: Piray
A42: 1-31472794 | B42: CACERES OSCAR | C42: 46071.417 | D42: 46071.422 | E42: 00:08 | F42: Piray
A43: 1-31472794 | B43: CACERES OSCAR | D43: 46071.762 | E43: 00:00 | F43: Piray
A44: 1-26184317 | B44: CENTURION LUCIANO | E44: 00:00 | F44: Piray
A45: 1-26184317 | B45: CENTURION LUCIANO | C45: 46080.382 | D45: 46080.419 | E45: 00:54 | F45: Piray
A46: 1-22233614 | B46: DAVALOS CESAR | C46: 46055.321 | D46: 46055.35 | E46: 00:42 | F46: Piray
A47: 1-22233614 | B47: DAVALOS CESAR | D47: 46055.748 | E47: 00:00 | F47: Piray
A48: 1-22233614 | B48: DAVALOS CESAR | C48: 46064.366 | D48: 46064.392 | E48: 00:38 | F48: Piray
A49: 1-22233614 | B49: DAVALOS CESAR | C49: 46064.719 | D49: 46064.725 | E49: 00:09 | F49: Piray
A50: 1-22233614 | B50: DAVALOS CESAR | D50: 46064.773 | E50: 00:00 | F50: Piray
A51: 1-22233614 | B51: DAVALOS CESAR | D51: 46071.408 | E51: 00:00 | F51: Piray
A52: 1-22233614 | B52: DAVALOS CESAR | D52: 46071.767 | E52: 00:00 | F52: Piray
A53: 1-22233614 | B53: DAVALOS CESAR | D53: 46073.387 | E53: 00:00 | F53: Piray
A54: 1-22233614 | B54: DAVALOS CESAR | D54: 46073.558 | E54: 00:00 | F54: Piray
A55: 1-22233614 | B55: DAVALOS CESAR | D55: 46074.3 | E55: 00:00 | F55: Piray
A56: 1-22233614 | B56: DAVALOS CESAR | D56: 46074.333 | E56: 00:00 | F56: Piray
A57: 1-22233614 | B57: DAVALOS CESAR | D57: 46078.351 | E57: 00:00 | F57: Piray
A58: 1-22233614 | B58: DAVALOS CESAR | C58: 46078.353 | D58: 46078.367 | E58: 00:21 | F58: Piray
A59: 1-22233614 | B59: DAVALOS CESAR | D59: 46078.656 | E59: 00:00 | F59: Piray
...

Sheet PARA AVISOS
A1: LOCALIDAD | B1: SEDE | C1: AREA | D1: CECO | E1: SECTOR/USUARIO | F1: DESCRIPCIÓN | G1: COD. EQUIPO | H1: FREC | I1: 43556 | J1: 43586 | K1: 43617 | L1: 43647 | M1: 43678 | N1: 43709 | O1: 43739 | P1: 43770 | Q1: 43800 | R1: 43831 | S1: 43862 | T1: 43891
A2: 10854101 | B2: PLANTA CELULOSA | C2: ADMINISTRACIÓN | D2: APOBA1-871 | E2: ESPE-ESP-CEL-ADMIN1-OFCOSTO1 | F2: TESORERIA-COSTOS | G2: CEL-AD1-17 | H2: 3 | O2: 3
A3: 10854106 | B3: PLANTA CELULOSA | C3: ADMINISTRACIÓN | D3: APOBA1-871 | E3: ESPE-ESP-CEL-ADMIN1-OFSECGTE | F3: OF. SECRETARIA GTE. | G3: CEL-AD1-19 | H3: 3 | O3: 3
A4: 10854123 | B4: PLANTA CELULOSA | C4: ADMINISTRACIÓN | D4: APOBA1-871 | E4: ESPE-ESP-CEL-ADMIN1-OFRRHH01 | F4: OF. RRHH CELULOSA | G4: CEL-AD1-2 | H4: 3 | O4: 3
A5: 10854186 | B5: PLANTA CELULOSA | C5: ADMINISTRACIÓN | D5: APOBA1-871 | E5: ESPE-ESP-CEL-ADMIN1-OFSGTEAD | F5: OF.SUBG.ADMINISTRACION. | G5: CEL-AD1-20 | H5: 3 | O5: 3
A6: 10854188 | B6: PLANTA CELULOSA | C6: ADMINISTRACIÓN | D6: APOBA1-871 | E6: ESPE-ESP-CEL-ADMIN1-OFSGTEMT | F6: OF. SUBGERENTE DE MTTO. | G6: CEL-AD1-21 | H6: 3 | O6: 3
A7: 10854202 | B7: PLANTA CELULOSA | C7: ADMINISTRACIÓN | D7: APOBA1-871 | E7: ESPE-ESP-CEL-ADMIN1-OFSGTEPR | F7: OF. SUBGERENTE DE PRODUCCIÓN. | G7: CEL-AD1-22 | H7: 3 | O7: 3
A8: 10854203 | B8: PLANTA CELULOSA | C8: ADMINISTRACIÓN | D8: APOBA1-871 | E8: ESPE-ESP-CEL-ADMIN1-OFJEFERH | F8: OF. JEFE DE RRHH. | G8: CEL-AD1-4 | H8: 3 | O8: 3
A9: 10854204 | B9: PLANTA CELULOSA | C9: ADMINISTRACIÓN | D9: APOBA1-871 | E9: ESPE-ESP-CEL-ADMIN1-OFAUINT1 | F9: OF. AUDITORIA INTERNA 1. | G9: CEL-AD1-5 | H9: 3 | O9: 3
A10: 10854205 | B10: PLANTA CELULOSA | C10: ADMINISTRACIÓN | D10: APOBA1-871 | E10: ESPE-ESP-CEL-ADMIN1-OFCONFO1 | F10: OF. CONTROL FORESTAL 1. | G10: CEL-AD1-8 | H10: 3 | O10: 3
A11: 10854206 | B11: PLANTA CELULOSA | C11: ADMINISTRACIÓN | D11: APOBA1-871 | E11: ESPE-ESP-CEL-ADMIN1-OFMASSO1 | F11: OF. MASSO 1. | G11: CEL-AD1-9 | H11: 3 | O11: 3
A12: 10854207 | B12: PLANTA CELULOSA | C12: ADMINISTRACIÓN 2 | D12: APOBA1-871 | E12: ESPE-ESP-CEL-ADMIN2-OFICINA1 | F12: OF. SUPERVISOR SSGG. | G12: CEL-AD2-1 | H12: 3 | O12: 3
A13: 10854208 | B13: PLANTA CELULOSA | C13: ADMINISTRACIÓN 2 | D13: APOBA1-871 | E13: ESPE-ESP-CEL-ADMIN2-OFCOYOB2 | F13: OF. CONTRATO Y OBRA 1 | G13: CEL-AD2-10 | H13: 3 | O13: 3
... A16: 10854232 | B16: PLANTA CELULOSA | C16: ADMINISTRACIÓN 2 | D16: APOBA1-871 | E16: ESPE-ESP-CEL-ADMIN2-OFCENPAG | F16: OF. CUENTAS A PAGAR | G16: CEL-AD2-2 | H16: 3 | O16: 3
A17: ESPERANZA | B17: PLANTA CELULOSA | C17: ADMINISTRACIÓN 2 | D17: APOBA1-871 | E17: Of. SSGG (Auxiliares 1) | G17: CEL-AD2-3 | H17: 3 | O17: 3
A18: ESPERANZA | B18: PLANTA CELULOSA | C18: ADMINISTRACIÓN 2 | D18: APOBA1-871 | E18: Of. SSGG (Movilidad) | G18: CEL-AD2-4 | H18: 3 | O18: 3
A19: ESPERANZA | B19: PLANTA CELULOSA | C19: ADMINISTRACIÓN 2 | D19: APOBA1-871 | E19: Of. Archivo Técnico | G19: CEL-AD2-5 | H19: 3 | O19: 3
A20: ESPERANZA | B20: PLANTA CELULOSA | C20: ADMINISTRACIÓN 2 | D20: APOBA1-871 | E20: Of. Cuentas a Pagar (Auxiliares) 1 | G20: CEL-AD2-8 | H20: 3 | P20: 3
A21: ESPERANZA | B21: PLANTA CELULOSA | C21: ADMINISTRACIÓN 2 | D21: APOBA1-871 | E21: Of. Cuentas a Pagar (Auxiliares) 2 | G21: CEL-AD2-9 | H21: 3 | P21: 3
A22: ESPERANZA | B22: PLANTA CELULOSA | C22: BALANZA | D22: APOBA1-871 | E22: Balanza A1 - B2 | G22: CEL-BAL-2 | H22: 2
A23: ESPERANZA | B23: PLANTA CELULOSA | C23: COMEDOR | D23: APOBA1-871 | E23: ESPE-ESP-CEL-COMEDO-MTTOAA01 | F23: MTTO AA 01 | G23: CEL-COM-1 | H23: 1 | I23: 1 | J23: 1 | K23: 1 | L23: 1 | M23: 1
A24: ESPERANZA | B24: PLANTA CELULOSA | C24: COMEDOR | D24: APOBA1-871 | E24: ESPE-ESP-CEL-COMEDO-MTTOAA02 | F24: MTTO AA 02 | G24: CEL-COM-2 | H24: 1 | I24: 1 | J24: 1 | K24: 1 | L24: 1 | M24: 1
A25: ESPERANZA | B25: PLANTA CELULOSA | C25: COMEDOR | D25: APOBA1-871 | E25: ESPE-ESP-CEL-COMEDO-MTTOAA03 | F25: MTTO AA 03 | G25: CEL-COM-3 | H25: 1 | I25: 1 | J25: 1 | K25: 1 | L25: 1 | M25: 1
A26: ESPERANZA | B26: PLANTA CELULOSA | C26: COMEDOR | D26: APOBA1-871 | E26: ESPE-ESP-CEL-COMEDO-MTTOAA04 | F26: MTTO AA 04 | G26: CEL-COM-4 | H26: 1 | I26: 1 | J26: 1 | K26: 1 | L26: 1 | M26: 1
A27: ESPERANZA | B27: PLANTA CELULOSA | C27: COMEDOR | D27: APOBA1-871 | E27: ESPE-ESP-CEL-COMEDO-MTTOAA05 | F27: MTTO AA 05 | G27: CEL-COM-5 | H27: 1 | I27: 1 | J27: 1 | K27: 1 | L27: 1 | M27: 1
A28: ESPERANZA | B28: PLANTA CELULOSA | C28: COMEDOR | D28: APOBA1-871 | E28: ESPE-ESP-CEL-COMEDO-MTTOAA06 | F28: MTTO AA 06 | G28: CEL-COM-6 | H28: 1 | K28: 1 | L28: 1 | M28: 1
A29: ESPERANZA | B29: PLANTA CELULOSA | C29: CONTROL TÉCNICO | D29: APOBA1-871 | E29: ESPE-ESP-CEL-LABORA-OFIC0019 | F29: OFICINA SUPERVISOR LAB. AGUAS/EFLUENTES | G29: CEL-COTE-4 | H29: 3 | P29: 3
A30: ESPERANZA | B30: PLANTA CELULOSA | C30: TRANSPORTE FORESTAL | D30: APOBA1-871 | E30: ESPE-ESP-CEL-FOREST-OFRECLOG | F30: Of. Auxiliares | G30: CEL-FOR-1 | H30: 2 | N30: 2
A31: ESPERANZA | B31: PLANTA CELULOSA | C31: TRANSPORTE FORESTAL | D31: APOBA1-871 | E31: ESPE-ESP-CEL-FOREST-OFJETRAN | F31: Of. Jefe de Carga y Transporte | G31: CEL-FOR-2 | H31: 2 | N31: 2
A32: ESPERANZA | B32: PLANTA CELULOSA | C32: TRANSPORTE FORESTAL | D32: APOBA1-871 | E32: ESPE-ESP-CEL-FOREST-SALREU01 | F32: Sala de reuniones (al lado de Recepción) | G32: CEL-FOR-3 | H32: 2 | N32: 2
A33: ESPERANZA | B33: PLANTA CELULOSA | C33: LOGISTICA | D33: APOBA1-871 | E33: Of. Trafico/Logistica 1 | G33: CEL-LOG-1 | H33: 3 | P33: 3
A34: ESPERANZA | B34: PLANTA CELULOSA | C34: LOGISTICA | D34: APOBA1-871 | E34: Of. Trafico/Logistica 1 | G34: CEL-LOG-2 | H34: 3 | P34: 3
A35: ESPERANZA | B35: PLANTA CELULOSA | C35: LOGISTICA | D35: APOBA1-871 | E35: Of. Jefe Logistica. | G35: CEL-LOG-3 | H35: 3 | P35: 3
A36: ESPERANZA | B36: PLANTA CELULOSA | C36: LOGISTICA | D36: APOBA1-871 | E36: Of. Planificacion Trafico/Logistica. | G36: CEL-LOG-4 | H36: 3 | P36: 3
A37: ESPERANZA | B37: PLANTA CELULOSA | C37: LOGISTICA | D37: APOBA1-871 | E37: Sala de Reunion | G37: CEL-LOG-5 | H37: 3 | P37: 3
A38: ESPERANZA | B38: PLANTA CELULOSA | C38: PORTERÍA | D38: APOBA1-871 | E38: Comedor | G38: CEL-POR-1 | H38: 3 | P38: 3
A39: ESPERANZA | B39: PLANTA CELULOSA | C39: PORTERÍA | D39: APOBA1-871 | E39: Of. Jefe de Equipo. | G39: CEL-POR-5 | H39: 3 | P39: 3
A40: ESPERANZA | B40: PLANTA CELULOSA | C40: SISTEMAS | D40: APOBA1-871 | E40: ESPE-ESP-CEL-SISTEM-OFICINA1 | F40: CENTRO DE COMPUTOS 1 | G40: CEL-SIST-1 | H40: 1 | I40: 1 | J40: 1 | K40: 1 | L40: 1 | M40: 1
A41: ESPERANZA | B41: PLANTA CELULOSA | C41: SISTEMAS | D41: APOBA1-871 | E41: ESPE-ESP-CEL-SISTEM-OFICINA2 | F41: CENTRO DE COMPUTOS 2 | G41: CEL-SIST-2 | H41: 1 | I41: 1 | J41: 1 | K41: 1 | L41: 1 | M41: 1
A42: ESPERANZA | B42: PLANTA CELULOSA | C42: SISTEMAS | D42: APOBA1-871 | E42: ESPE-ESP-CEL-SISTEM-OFICINA3 | F42: CENTRAL TELEFÓNICA | G42: CEL-SIST-3 | H42: 1 | I42: 1 | J42: 1 | K42: 1 | L42: 1 | M42: 1
...

Sheet Hoja1
A3: SECTOR/USUARIO | B3: DESCRIPCIÓN | D3: COD. EQUIPO | E3: COD. NUEVO
A4: ESPE-ESP-CEL-ADMIN1-OFRRHH01 | B4: OF. RRHH CELULOSA | D4: CEL-AD1-1 | E4: CEL-AD1-1
A5: Of. RRHH (Auxiliares) 2 | B5: Of. RRHH (Auxiliares) 2 | D5: CEL-AD1-2 | E5: CEL-AD1-2
A6: ESPE-ESP-CEL-ADMIN1-SALREU01 | B6: SALA DE REUNIONES RR.HH. | D6: CEL-AD1-3 | E6: CEL-AD1-3
A7: ESPE-ESP-CEL-ADMIN1-OFJEFERH | B7: Of. Jefe de Área RRHH | D7: CEL-AD1-4 | E7: CEL-AD1-4
A8: ESPE-ESP-CEL-ADMIN1-OFAUINT1 | B8: Of. Jefe Auditoría Interna | D8: CEL-AD1-5 | E8: CEL-AD1-5
A9: ESPE-ESP-CEL-ADMIN1-OFAUINT2 | B9: Of. Auditoría Interna (Auxiliar) | D9: CEL-AD1-6 | E9: CEL-AD1-6
A10: ESPE-ESP-CEL-ADMIN1-OFCONFO2 | B10: Of. Control Forestal (Auxiliares) | D10: CEL-AD1-8 | E10: CEL-AD1-7
A11: ESPE-ESP-CEL-ADMIN1-OFMASSO3 | B11: DANIEL CABRERA | D11: CEL-AD1-15 | E11: CEL-AD1-8
A12: ESPE-ESP-CEL-ADMIN1-OFCOSTO1 | B12: Of. Costos (Auxiliares) | D12: CEL-AD1-11 | E12: CEL-AD1-9
A13: ESPE-ESP-CEL-ADMIN1-OFCONPRO | B13: Of. Control de Producción | D13: CEL-AD1-7 | E13: CEL-AD1-10
A14: ESPE-ESP-CEL-ADMIN1-OFMASSO3 | B14: OF. JEFE DE SEGURIDAD. GRACIELA BENITEZ | D14: CEL-AD1-10 | E14: CEL-AD1-11
... A29: ESPE-ESP-CEL-ADMIN1-OFSECGTE | B29: Of. Secretaria Gte. | D29: CEL-AD1-19 | E29: CEL-AD1-26
B30: OFICINAS SOEP | E30: CEL-AD1-27
B31: OFICINA DE VICITAS GERENCIA | E31: CEL-AD1-28
A34: SECTOR/USUARIO | B34: DESCRIPCIÓN | C34: DESCRIPCION NUEVA | D34: COD. EQUIPO | E34: COD. NUEVO
A35: YPOR-YPO-GOF-ADMIN1-OFIC0010 | B35: OFICINA DEL secretaria GTE FORESTAL | C35: OFICINA 01 SECRETARIA DE GERENCIA | D35: PYP-AD1-10 | E35: PYP-AD1-10
A36: YPOR-YPO-GOF-ADMIN1-OFIC0011 | B36: OFICINA DE SYSO (LANG) | C36: OFICIAN 02 SYSO | D36: PYP-AD1-11 | E36: PYP-AD1-11
A37: YPOR-YPO-GOF-ADMIN1-OFIC0012 | B37: OFICINA DE CARTOGRAFIA | C37: OFICINA 03 CARTOGRAFIA | D37: PYP-AD1-12 | E37: PYP-AD1-12
A38: YPOR-YPO-GOF-ADMIN1 | B38: Of. Abastecimiento - Ventas y Planificación | C38: OFICIANA 04 | D38: PYP-AD1-13 | E38: PYP-AD1-13
A39: YPOR-YPO-GOF-ADMIN1-OFIC0014 | B39: Of. Control de Producción 1 | C39: OFICINA 05 | D39: PYP-AD1-14 | E39: PYP-AD1-14
A40: YPOR-YPO-GOF-ADMIN1-OFIC0015 | B40: Of. Control de Producción 2 (Oficina N° 3) | C40: OFICINA 06 | D40: PYP-AD1-15 | E40: PYP-AD1-15
A41: YPOR-YPO-GOF-ADMIN1 | B41: VACIA | C41: OFICINA 07 | D41: PYP-AD1-16 | E41: PYP-AD1-16
A42: YPOR-YPO-GOF-ADMIN1-OFIC0036 | B42: OF. RRHH (ML BOYCO) | C42: OFICINA 08 BOYCO LORENA | D42: PYP-AD1-17 | E42: PYP-AD1-17
A43: YPOR-YPO-GOF-ADMIN1-OFIC0019 | B43: Of. SySO (Lang Julio) | C43: OFICINA 09 | D43: PYP-AD1-18 | E43: PYP-AD1-18
A44: YPOR-YPO-GOF-ADMIN1-OFIC0020 | B44: Of. Control Forestal | C44: OFICIAN 10 | D44: PYP-AD1-19 | E44: PYP-AD1-19
A45: YPOR-YPO-GOF-ADMIN1-OFIC0020 | B45: Of. De Costos | C45: OFICINA 11 | D45: PYP-AD1-20 | E45: PYP-AD1-20
... A63: YPOR-YPO-GOF-ADMIN1 | B63: Of. De Jefe (De Oliveira A.) | C63: OFICINA 25 | D63: PYP-AD1-9 | E63: PYP-AD1-8
A64: YPOR-YPO-GOF-ADMIN1 | C64: NUEVA ALA TECNICA | E64: PYP-AD1-30
A65: YPOR-YPO-GOF-ADMIN1 | C65: NUEVA ALA TECNICA | E65: PYP-AD1-31
A66: YPOR-YPO-HOT-HOTEL1-HALLINGR | B66: HALL INGRESO | D66: PYP-HOS-1
A67: YPOR-YPO-HOT-PLANTB-HABITA04 | B67: HABITACIÓN 4 | D67: PYP-HOS-10
A68: YPOR-YPO-HOT-PLANTB-HABITA05 | B68: HABITACIÓN 5 | D68: PYP-HOS-11
A69: YPOR-YPO-HOT-PLANTB-HABITA06 | B69: HABITACIÓN 6 | D69: PYP-HOS-12
A70: YPOR-YPO-HOT-PLANTB-HABITA07 | B70: HABITACIÓN 7 | D70: PYP-HOS-7
A71: YPOR-YPO-HOT-PLANTB-HABITA08 | B71: HABITACIÓN 8 | D71: PYP-HOS-8
A72: YPOR-YPO-HOT-PLANTB-HABITA09 | B72: HABITACIÓN 9 | D72: PYP-HOS-9
A73: YPOR-YPO-HOT-PLANTA-HABITA10 | B73: HABITACIÓN 10 | D73: PYP-HOS-16
A74: YPOR-YPO-HOT-PLANTA-HABITA11 | B74: HABITACIÓN 11 | D74: PYP-HOS-17
A75: YPOR-YPO-HOT-PLANTA-HABITA12 | B75: HABITACIÓN 12 | D75: PYP-HOS-18
...
